Workbook
Name A: {"'TG'!$A$1:$L$37"}
Name A: {"'TG'!$A$1:$L$37"}
Name A: {"'TG'!$A$1:$L$37"}
Name A: {"'TG'!$A$1:$L$37"}
Name A: {"'TG'!$A$1:$L$37"}
Name A: {"'TG'!$A$1:$L$37"}
Name A: {"'TG'!$A$1:$L$37"}
Name A: {"'TG'!$A$1:$L$37"}
Name Comprar: #REF!
Name Comprar: #REF!
Name Comprar: #REF!
Name Comprar: #REF!
Name Comprar: #REF!
Name Comprar: #REF!
Name Comprar: #REF!
Name Início_do_projeto: #REF!
Name Início_do_projeto: #REF!
Name Início_do_projeto: #REF!
Name Início_do_projeto: #REF!
Name Início_do_projeto: #REF!
Name Início_do_projeto: #REF!
Name Início_do_projeto: #REF!
Name Periodicidade: Param!$AB$5:$AB$9
Name Periodicidade: #REF!
Name Periodicidade: #REF!
Name Semana_de_exibição: #REF!
Name Semana_de_exibição: #REF!
Name Semana_de_exibição: #REF!
Name Semana_de_exibição: #REF!
Name Semana_de_exibição: #REF!
Name Semana_de_exibição: #REF!
Name Semana_de_exibição: #REF!
Name Semana_de_exibição: #REF!
Name Status: #REF!
Name Status: #REF!
Name Status: #REF!
Name Status: #REF!
Name Status: #REF!
Name Status: #REF!
Name Status: #REF!
Name t: {"'TG'!$A$1:$L$37"}
Name t: {"'TG'!$A$1:$L$37"}
Name t: {"'TG'!$A$1:$L$37"}
Name t: {"'TG'!$A$1:$L$37"}
Name t: {"'TG'!$A$1:$L$37"}
Name t: {"'TG'!$A$1:$L$37"}
Name t: {"'TG'!$A$1:$L$37"}
Name t: {"'TG'!$A$1:$L$37"}
Name VersaoExcel: Param!$D$15:$E$15
Name VersaoExcel: #REF!
Name VersaoExcel: #REF!
Name VersaoSR: Param!$C$24:$C$26
Name VersaoSR: #REF!
Name VersaoSR: #REF!

Sheet Project Charter

Sheet WBS-MACRO-ATIVIDADE

Sheet WBS_Detalhado (ordem etapas)
B7: 4.1 Plano de ação detalhado da WBS (com dependência, tempo e recurso) | O7: FAREMOS MAIS PARA FRENTE
B9: Ref | C9: Etapas – Atividades - | D9: Dependência | E9: Data Início | F9: Data Fim | G9: Duração em dias | H9: Conclusão (ENTREGA) | I9: Responsável | J9: Recursos | K9: Custos | L9: Obs | N9: Rede de Precedência de Atividades
B10: 1 | C10: Iniciação | O10: Atividades | P10: Dependência | Q10: Duração em semanas
B11: 1.1 | C11: Definição dos objetivos dos dashboards | E11: 45880 | F11: 45882 | G11: 2 | H11: 1ª | I11: EQUIPE | J11: Pessoas | K11: 100 | N11: 1 | O11: Iniciação | P11: NÃO | Q11: 1
B12: 1.2 | C12: Formação da equipe e definição dos papéis | E12: =F11+1 -> 45883 | F12: =E12+G12 -> 45884 | G12: 1 | H12: 1ª | I12: EQUIPE | J12: Pessoas | K12: 100 | N12: 2 | O12: Planejamento | P12: Iniciação | Q12: 2
B13: 1.3 | C13: Levantamento inicial de requisitos e funcionalidades | D13: 1.1 e 1.2 | E13: =F12+1 -> 45885 | F13: =E13+G13 -> 45888 | G13: 3 | H13: 1ª | I13: EQUIPE | J13: Pessoas | K13: 100 | N13: 3 | O13: Design e Prototipagem | P13: Iniciação | Q13: 2
B14: 2.0 | C14: Planejamento | D14: 2.0 | H14: 1ª | K14: =SUM(K11:K13) -> 300 | N14: 4 | O14: Desenvolvimento | P14: Planejamento/Design e Prototipagem | Q14: 12
B15: 2.1 | C15: Análise de necessidades da Cannoli e clientes | D15: 1.3 | E15: =F13+1 -> 45889 | F15: =G15+E15 -> 45893 | G15: 4 | H15: 1ª | I15: EQUIPE | J15: Pessoas | K15: 500 | N15: 5 | O15: Integração com sistemas de monitoramento de saúde | P15: Desenvolvimento | Q15: 8
B16: 2.2 | C16: Definição de requisitos funcionais e não funcionais | D16: 2.1 | E16: =F15+1 -> 45894 | F16: =G16+E16 -> 45897 | G16: 3 | H16: 1ª | I16: EQUIPE | J16: Pessoas | K16: 500 | N16: 6 | O16: Testes | P16: Integração com sistemas de monitoramento de saúde | Q16: 3
B17: 2.3 | C17: Elaboração do cronograma e metas | D17: 2.2 | E17: =F16+1 -> 45898 | F17: =G17+E17 -> 45899 | G17: 1 | H17: 1ª | I17: EQUIPE | J17: Pessoas | K17: 500 | N17: 7 | O17: Lançamento (Stakeholders internos) | P17: Testes | Q17: 2
B18: 2.4 | C18: Identificação de riscos e plano de mitigação | D18: 2.3 | E18: =F17+1 -> 45900 | F18: =G18+E18 -> 45904 | G18: 4 | H18: 1ª | I18: EQUIPE | J18: Pessoas | K18: 500 | N18: 8 | O18: Pós-lançamento (Stakeholders internos) | P18: Lançamento (Stakeholders internos) | Q18: 1
B19: 3.0 | C19: Design e Prototipagem | D19: 3.0 | H19: 1ª | K19: =SUM(K15:K18) -> 2000
B20: 3.1 | C20: DESIGN UI | D20: 2.4 | H20: 1ª | I20: EQUIPE | J20: Pessoas | K20: 50
B21: 3.2 | C21: Navegação e funcionalidades | D21: 2.4 | E21: =F18+1 -> 45905 | F21: =G21+E21 -> 45910 | G21: 5 | H21: 1ª | I21: EQUIPE | J21: Pessoas | K21: 50
B22: 3.3 | C22: Protótipos interativos | D22: 2.4 | E22: =F21+1 -> 45911 | F22: =E22+G22 -> 45914 | G22: 3 | H22: 1ª | I22: EQUIPE | J22: Pessoas | K22: 50
B23: 3.4 | C23: DESIGN UX | D23: 3.2 e 3.3 | H23: 1ª | I23: EQUIPE | J23: Pessoas | K23: 50
B24: 3.5 | C24: Interface limpa e intuitiva | D24: 3.2 e 3.3 | E24: =F22+1 -> 45915 | F24: =E24+G24 -> 45917 | G24: 2 | H24: 1ª | I24: EQUIPE | J24: Pessoas | K24: 50
B25: 3.6 | C25: Teste de UI / UX | D25: 3.2, 3.3, 3.5 | E25: =F24+1 -> 45918 | F25: =E25+G25 -> 45919 | G25: 1 | H25: 1ª | I25: EQUIPE | J25: Pessoas | K25: 50
B26: 4.0 | C26: Desenvolvimento | D26: 4.0 | H26: 1ª e 2ª | K26: =SUM(K20:K25) -> 300
B27: 4.1 | C27: Modelagem de dados e definição da arquitetura | D27: 3.6 | E27: =F25+1 -> 45920 | F27: =E27+G27 -> 45927 | G27: 7 | H27: 1ª | I27: EQUIPE | J27: Pessoas | K27: 1000
B28: 4.2 | C28: Implementação do frontend (gráficos, filtros, KPIs) | D28: 4.1 | E28: =F27+1 -> 45928 | F28: =E28+G28 -> 45931 | G28: 3 | H28: 1ª | I28: EQUIPE | J28: Pessoas | K28: 1000
B29: 4.3 | C29: Implementação do backend (API, lógica do negócio, segurança) | D29: 4.2 | E29: =F28+1 -> 45932 | F29: =E29+G29 -> 45946 | G29: 14 | H29: 2ª | I29: EQUIPE | J29: Pessoas | K29: 1000
B30: 4.4 | C30: Integração com base de dados | D30: 4.3 | E30: =F29+1 -> 45947 | F30: =E30+G30 -> 45948 | G30: 1 | H30: 2ª | I30: EQUIPE | J30: Pessoas | K30: 1000
B31: 5.0 | C31: INTEGRAÇÃO DE INTELIGÊNCIA ARTIFICIAL E SIMULAÇÕES | D31: 5.0 | H31: 1ª | K31: =SUM(K27:K30) -> 4000
B32: 5.1 | C32: Aplicação de algoritmos de IA/ML | D32: 4.4 | E32: =F30+1 -> 45949 | F32: =G32+E32 -> 45951 | G32: 2 | H32: 2ª | I32: EQUIPE | J32: Pessoas | K32: 1200
B33: 5.2 | C33: Implementação de alertas automáticos e detecção de anomalias | D33: 5.1 | E33: =F32+1 -> 45952 | F33: =G33+E33 -> 45953 | G33: 1 | H33: 2ª | I33: EQUIPE | J33: Pessoas | K33: 1200
B34: 5.3 | C34: Simulação de campanhas e cenários de uso | D34: 5.2 | E34: =F33+1 -> 45954 | F34: =G34+E34 -> 45955 | G34: 1 | H34: 2ª | I34: EQUIPE | J34: Pessoas | K34: 1200
B35: 6.0 | C35: Testes | D35: 6.0 | H35: 2ª | K35: 3600
B36: 6.1 | C36: Testes funcionais e de usabilidade | D36: 5.3 | E36: =F34+1 -> 45956 | F36: =G36+E36 -> 45957 | G36: 1 | H36: 2ª | I36: EQUIPE | J36: Pessoas | K36: 500
B37: 6.2 | C37: Testes de responsividade e compatibilidade | D37: 6.1 | E37: =F36+1 -> 45958 | F37: =G37+E37 -> 45959 | G37: 1 | H37: 2ª | I37: EQUIPE | J37: Pessoas | K37: 500
B38: 6.3 | C38: Testes de segurança e privacidade (LGPD) | D38: 6.2 | E38: =F37+1 -> 45960 | F38: =G38+E38 -> 45961 | G38: 1 | H38: 2ª | I38: EQUIPE | J38: Pessoas | K38: 500
B39: 7.0 | C39: Lançamento (Stakeholders internos) | D39: 7.0 | H39: 2ª | K39: =SUM(K36:K38) -> 1500
B40: 7.1 | C40: Preparar a infraestrutura para o lançamento nas lojas de aplicativos (App Store, Google Play) | D40: 6.3 | E40: =F38+1 -> 45962 | F40: =G40+E40 -> 45963 | G40: 1 | H40: 2ª | I40: EQUIPE | J40: Pessoas | K40: 7500
B41: 7.2 | C41: Criar materiais de marketing, como vídeos promocionais e descrições claras | D41: 6.3 | E41: =F40+1 -> 45964 | F41: =G41+E41 -> 45965 | G41: 1 | H41: 2ª | I41: EQUIPE | J41: Pessoas | K41: 6600
A42: . | B42: 7.3 | C42: Submeter o aplicativo para revisão nas lojas de aplicativos | D42: 6.3 | E42: =F41+1 -> 45966 | F42: =G42+E42 -> 45967 | G42: 1 | H42: 2ª | I42: EQUIPE | J42: Pessoas | K42: 4500
B43: 8.0 | C43: Pós-lançamento (Stakeholders internos) | D43: 8.0 | H43: 2ª | K43: =SUM(K40:K42) -> 18600
B44: 8.1 | C44: Entrega da primeira versão aos professores | D44: 6.3 | E44: =F42+1 -> 45968 | F44: =G44+E44 -> 45969 | G44: 1 | H44: 2ª | I44: EQUIPE | J44: Pessoas | K44: 0
B45: 8.2 | C45: Ajustes baseados em feedbacks | D45: 8.1 | E45: =F44+1 -> 45970 | F45: =G45+E45 -> 45971 | G45: 1 | H45: 2ª | I45: EQUIPE | J45: Pessoas | K45: 0
B46: 8.3 | C46: Entrega oficial da versão final | D46: 8.2 | E46: =F45+1 -> 45972 | F46: =G46+E46 -> 45973 | G46: 1 | H46: 2ª | I46: EQUIPE | J46: Pessoas | K46: 0
B47: 9.0 | C47: PÓS-LANÇAMENTO E APRESENTAÇÃO FINAL | D47: 9.0 | K47: =SUM(K44:K46) -> 0
...

Sheet WBS_Detalhado (ordem depend)
B6: 4.2 Plano de ação detalhado da WBS (com dependência, tempo e recurso)
B8: Ref | C8: Etapas – Atividades - | D8: Dependência | E8: Duração em dias | F8: Conclusão | G8: Responsável | H8: Recursos | I8: Obs
B9: 1 | C9: Iniciação | D9: 1 | E9: 1
B10: 1.1 | C10: Definição dos objetivos dos dashboards | D10: 1.1 | E10: 1 | F10: 1ª | G10: EQUIPE | H10: Pessoas | I10: -
B11: 1.2 | C11: Formação da equipe e definição dos papéis | D11: 1.2 | E11: 1 | F11: 1ª | G11: EQUIPE | H11: Pessoas | I11: -
B12: 1.1 | C12: Definição dos objetivos dos dashboards | D12: 1.1 | G12: EQUIPE
B13: 1.2 | C13: Formação da equipe e definição dos papéis | D13: 1.2 | E13: 1 | G13: EQUIPE
B14: 1.3 | C14: Levantamento inicial de requisitos e funcionalidades | D14: 1.1 e 1.2 | E14: 1 | F14: 1ª | G14: EQUIPE | H14: Pessoas | I14: -
B15: 2.0 | C15: Planejamento | E15: 1 | G15: EQUIPE
B16: 2.1 | C16: Análise de necessidades da Cannoli e clientes | D16: 1.3 | F16: 1ª | G16: EQUIPE | H16: Pessoas | I16: -
B17: 2.2 | C17: Definição de requisitos funcionais e não funcionais | D17: 2.1 | E17: 1 | F17: 1ª | G17: EQUIPE | H17: Pessoas | I17: -
B18: 2.3 | C18: Elaboração do cronograma e metas | D18: 2.2 | E18: 1 | F18: 1ª | G18: EQUIPE | H18: Pessoas | I18: -
B19: 2.4 | C19: Identificação de riscos e plano de mitigação | D19: 2.3 | E19: 1 | F19: 1ª | G19: EQUIPE | H19: Pessoas | I19: -
B20: 3.0 | C20: Design e Prototipagem
B21: 3.1 | C21: DESIGN UI | D21: 2.4 | E21: 1 | F21: 1ª | G21: EQUIPE | H21: Pessoas | I21: -
B22: 3.2 | C22: Navegação e funcionalidades | D22: 2.4 | E22: 1 | F22: 1ª | G22: EQUIPE | H22: Pessoas | I22: -
B23: 3.3 | C23: Protótipos interativos | D23: 2.4 | E23: 1 | F23: 1ª | G23: EQUIPE | H23: Pessoas | I23: -
B24: 3.4 | C24: DESIGN UX | D24: 3.2, 3.3 | E24: 1 | F24: 1ª | G24: EQUIPE | H24: Pessoas | I24: -
B25: 3.5 | C25: Interface limpa e intuitiva | D25: 3.2, 3.3 | E25: 2 | F25: 2ª | G25: EQUIPE | H25: Pessoas | I25: -
B26: 3.6 | C26: Teste de UI / UX | D26: 3.2, 3.3, 3.5 | E26: 2 | F26: 2ª | G26: EQUIPE | H26: Pessoas | I26: -
B27: 4.0 | C27: Desenvolvimento
B28: 4.1 | C28: Modelagem de dados e definição da arquitetura | D28: 3.6 | E28: 1 | F28: 1ª | G28: EQUIPE | H28: Pessoas | I28: -
B29: 4.2 | C29: Implementação do backend (API, lógica do negócio, segurança) | D29: 4.1 | E29: 2 | F29: 1ª | G29: EQUIPE | H29: Pessoas | I29: -
B30: 4.3 | C30: Implementação do frontend (gráficos, filtros, KPIs) | D30: 4.2 | E30: 1 | F30: 2ª | G30: EQUIPE | H30: Pessoas | I30: -
B31: 4.4 | C31: Integração com base de dados | D31: 4.3 | E31: 1 | F31: 2ª | G31: EQUIPE | H31: Pessoas | I31: -
B32: 5.0 | C32: INTEGRAÇÃO DE INTELIGÊNCIA ARTIFICIAL E SIMULAÇÕES
B33: 5.1 | C33: Aplicação de algoritmos de IA/ML para gerar insights | D33: 4.4 | E33: 1 | F33: 2ª | G33: EQUIPE | H33: Pessoas | I33: -
B34: 5.2 | C34: Implementação de alertas automáticos e detecção de anomalias | D34: 5.1 | E34: 1 | F34: 2ª | G34: EQUIPE | H34: Pessoas | I34: -
B35: 5.3 | C35: Simulação de campanhas e cenários de uso | D35: 5.2 | E35: 1 | F35: 1ª | G35: EQUIPE | H35: Pessoas | I35: -
B36: 6.0 | C36: Testes
B37: 6.1 | C37: Testes funcionais e de usabilidade | D37: 5.3 | E37: 2 | F37: 2ª | G37: EQUIPE | H37: Pessoas | I37: -
B38: 6.2 | C38: Testes de responsividade e compatibilidade | D38: 6.1 | E38: 2 | F38: 2ª | G38: EQUIPE | H38: Pessoas | I38: -
B39: 6.3 | C39: Testes de segurança e privacidade (LGPD) | D39: 6.2 | E39: 2 | F39: 2ª | G39: EQUIPE | H39: Pessoas | I39: -
B40: 7.0 | C40: Lançamento (Stakeholders internos)
B41: 7.1 | C41: Preparar a infraestrutura para o lançamento nas lojas de aplicativos (App Store, Google Play) | D41: 6.3 | E41: 2 | F41: 2ª | G41: EQUIPE | H41: Pessoas | I41: -
B42: 7.2 | C42: Criar materiais de marketing, como vídeos promocionais e descrições claras | D42: 6.3 | E42: 2 | F42: 2ª | G42: EQUIPE | H42: Pessoas | I42: -
B43: 7.3 | C43: Submeter o aplicativo para revisão nas lojas de aplicativos | D43: 6.3 | E43: 2 | F43: 2ª | G43: EQUIPE | H43: Pessoas | I43: -
B44: 8.0 | C44: Pós-lançamento (Stakeholders internos)
B45: 8.1 | C45: Entrega da primeira versão aos professores | D45: 6.3 | E45: 2 | F45: 2ª | G45: EQUIPE | H45: Pessoas | I45: -
B46: 8.2 | C46: Ajustes baseados em feedbacks | D46: 8.1 | E46: 2 | F46: 2ª | G46: EQUIPE | H46: Pessoas | I46: -
...

Sheet Análise de Stackeholder
A1: Mapa de Avaliação de Stakeholders - SAM | H1: Matriz de Relatórios Stakeholders – SRM
A2: Stakeholder | B2: Objetivos, Metas, Motivações e Interesses | C2: Poder e Influência | D2: Importância e Impacto | E2: Papéis & Responsabilidades | F2: Sintonia “fina” | H2: Stakeholder | I2: Área de Interesse | J2: Nível de Detalhe | K2: Formato | L2: Frequência | M2: Mecanismo de Entrega
A3: Cliente (Usuários Finais) | B3: Ter acesso a relatórios claros, KPIs e insights para apoiar decisões de negócio; experiência intuitiva e responsiva. | C3: Médio (feedback influencia melhorias e ajustes). | D3: Alto, pois são os principais beneficiários e validadores da solução. | E3: Utilizar o sistema, fornecer feedback contínuo. | F3: Envolvimento em testes de usabilidade e validação. | H3: Cliente (Usuários Finais) | I3: KPIs, relatórios customizáveis, facilidade de uso do dashboard. | J3: Resumos claros com indicadores principais. | K3: Demonstrações práticas, dashboards interativos, tutoriais. | L3: Durante testes e validação final. | M3: Workshops, formulários de feedback, demonstrações online.
A4: Product Owner | B4: Garantir que o dashboard atenda às necessidades estratégicas da Cannoli. | C4: Alto, define prioridades, aceita ou rejeita entregas. | D4: Muito alto, direciona o desenvolvimento. | E4: Gerir backlog, priorizar funcionalidades, validar entregas. | F4: Contato frequente com a equipe de desenvolvimento. | H4: Product Owner (Equipe Cannoli/Admins) | I4: KPIs estratégicos, relatórios exportáveis, usabilidade e segurança. | J4: Visão executiva, resultados de negócio. | K4: Relatórios de desempenho, apresentações de status. | L4: A cada entrega (sprint review). | M4: Reuniões online, relatórios PDF/Excel.
A5: Desenvolvedores | B5: Entregar um produto funcional, seguro e inovador dentro do prazo e escopo. | C5: Médio, pois possuem domínio técnico mas seguem prioridades definidas pelo Product Owner. | D5: Alto, responsáveis pela execução. | E5: Implementação de backend, frontend, integrações e testes. | F5: Trabalho colaborativo, reuniões semanais, aplicação de boas práticas. | H5: Desenvolvedores (Equipe de alunos) | I5: Backlog, requisitos técnicos, progresso do sprint. | J5: Detalhes técnicos e de gestão do progresso. | K5: Quadro Kanban, relatórios de sprint, dailys. | L5: Diário/semanal. | M5: Reuniões presenciais/Teams, Trello/Jira.
A6: Time Comercial | B6: Usar dados estratégicos para atrair e fidelizar clientes; melhorar performance de vendas. | C6: Médio, podem solicitar métricas específicas. | D6: Alto, dashboard gera valor direto para decisões comerciais. | E6: Validar indicadores comerciais, sugerir métricas relevantes. | F6: Feedback durante testes e uso. | H6: Time Comercial | I6: Estratégias de vendas, métricas de clientes, potencial de uso do dashboard. | J6: Resumos claros de oportunidades e métricas. | K6: Relatórios de impacto de negócio. | L6: Trimestral. | M6: Reuniões estratégicas, e-mail.
A7: Marketing | B7: Obter relatórios e métricas de engajamento para campanhas mais efetivas. | C7: Médio. | D7: Médio-Alto, pois impacta diretamente a visibilidade da empresa. | E7: Indicar necessidades de métricas de marketing. | F7: Feedback contínuo sobre relatórios de campanhas. | H7: Marketing | I7: Engajamento dos clientes, divulgação da plataforma Cannoli. | J7: Resumo visual de resultados e alcance. | K7: Relatórios de comunicação, métricas de engajamento. | L7: Mensal. | M7: E-mails, apresentações visuais.
A8: UX (User Experience) | B8: Garantir que a interface seja intuitiva, acessível e responsiva. | C8: Médio, influencia na aceitação do sistema. | D8: Alto, experiência ruim pode comprometer o sucesso do projeto. | E8: Prototipagem, testes de usabilidade e ajustes de interface. | F8: Alinhamento constante com desenvolvedores. | H8: UX (User Experience) | I8: Usabilidade da interface, feedback dos usuários. | J8: Feedback detalhado sobre navegação e experiência. | K8: Protótipos, testes de usabilidade, relatórios UX. | L8: Durante design e testes. | M8: Sessões de testes com usuários, relatórios UX.
A9: Equipe de Suporte ao Cliente | B9: Garantir que clientes consigam usar a plataforma sem dificuldades. | C9: Baixo-Médio. | D9: Médio, pois atuam diretamente na satisfação do cliente. | E9: Suporte técnico, registro de problemas e feedback. | F9: Participação em testes e treinamento. | H9: Equipe de Suporte ao Cliente | I9: Demandas dos usuários finais, resolução de problemas. | J9: Relatórios práticos de incidentes e soluções. | K9: Registro de chamados, relatórios de suporte. | L9: Semanal. | M9: Sistema de tickets, reuniões de alinhamento.
A10: Gerência Executiva/Alta Administração | B10: Alinhar o aplicativo com a visão da empresa e garantir o sucesso financeiro e da marca no mercado. | C10: Muito alto, patrocinadores e tomadores de decisão. | D10: Muito alto, aprovam e validam a entrega final. | E10: Aprovação de recursos, validação estratégica. | F10: Reuniões de acompanhamento e entrega de relatórios. | H10: Gerência Executiva / Alta Administração | I10: Visão estratégica, impacto nos negócios, ROI. | J10: Relatórios executivos, visão macro. | K10: Apresentações de resultados, relatórios consolidados. | L10: Em marcos principais (validações e entrega final). | M10: Reuniões executivas, relatórios em PDF.

Sheet Diagrama de Seta
A10: Projeto para construir um SISTEMA | J10: Diagrama de seta
K11: Atividade fantasma
B12: Quantos Dias dura o projeto?
F13: Dias
A14: Desenvolvimento APP | B14: Atividade | C14: Dependência | D14: Duração | F14: 1 | G14: 2 | H14: 3 | I14: 4 | J14: 5 | K14: 6 | L14: 7 | M14: 8 | N14: 9 | O14: 10 | P14: 11 | Q14: 12 | R14: 13 | S14: 14 | T14: 15 | U14: 16 | V14: 17 | W14: 18 | X14: 19 | Y14: 20 | Z14: 21 | AA14: 22 | AB14: 23 | AC14: 24 | AD14: 25 | AE14: 26 | AF14: 27 | AG14: 28 | AH14: 29 | AI14: 30 | AJ14: 31 | AK14: 32 | AL14: 33 | AM14: 34 | AN14: 35 | AO14: 36 | AP14: 37 | AQ14: 38 | AR14: 39 | AS14: 40 | AT14: 41 | AU14: 42 | AV14: 43 | AW14: 44 | AX14: 45 | AY14: 46 | AZ14: 47 | BA14: 48 | BB14: 49 | BC14: 50 | BD14: 51 | BE14: 52 | BF14: 53 | BG14: 54 | BH14: 55 | BI14: 56 | BJ14: 57 | BK14: 58 | BL14: 59 | BM14: 60 | BN14: 61 | BO14: 62 | BP14: 63 | BQ14: 64 | BR14: 65 | BS14: 66 | BT14: 67 | BU14: 68 | BV14: 69
A15: Definição dos objetivos dos dashboards | B15: 1.1 | D15: 2
A16: Formação da equipe e definição dos papéis | B16: 1.2 | D16: 1 | AM16: 4.2 | AP16: 4.3 | BM16: 7.3
A17: Levantamento inicial de requisitos e funcionalidades | B17: 1.3 | C17: 1.1 e 1.2 | D17: 3 | BL17: 7.2 | BN17: 8.1
A18: Análise de necessidades da Cannoli e clientes | B18: 2.1 | C18: 1.3 | D18: 4 | BK18: 7.1 | BO18: 8.2
A19: Definição de requisitos funcionais e não funcionais | B19: 2.2 | C19: 2.1 | D19: 3 | R19: 2.3 | AC19: 3.5 | AE19: 3.6 | AF19: 4.1 | BJ19: 6.3 | BP19: 8.3 | BQ19: 9.1 | BR19: 9.2 | BS19: 9.3
A20: Elaboração do cronograma e metas | B20: 2.3 | C20: 2.2 | D20: 1 | K20: 2.1 | O20: 2.2 | S20: 2.4 | X20: 3.2 | BG20: 5.3 | BH20: 6.1 | BI20: 6.2
A21: Identificação de riscos e plano de mitigação | B21: 2.4 | C21: 2.3 | D21: 4 | F21: 1.1 | Y21: 3.3 | BF21: 5.2
A22: Navegação e funcionalidades | B22: 3.2 | C22: 2.4 | D22: 5 | H22: 1.3 | BE22: 5.1
A23: Protótipos interativos | B23: 3.3 | C23: 2.4 | D23: 3 | F23: 1.2 | BC23: 4.4
A24: Interface limpa e intuitiva | B24: 3.5 | C24: 3.2 e 3.3 | D24: 2
A25: Teste de UI / UX | B25: 3.6 | C25: 3.2, 3.3, 3.5 | D25: 1
A26: Modelagem de dados e definição da arquitetura | B26: 4.1 | C26: 3.6 | D26: 7
A27: Implementação do frontend (gráficos, filtros, KPIs) | B27: 4.2 | C27: 4.1 | D27: 3
A28: Implementação do backend (API, lógica do negócio, segurança) | B28: 4.3 | C28: 4.2 | D28: 14 | F28: Quantos dias dura o Projeto? 46 | K28: 67
A29: Integração com base de dados | B29: 4.4 | C29: 4.3 | D29: 1 | F29: Quais as atividades não podem atrasar? A, B, D, F,G --> caminho crítico | M29: 2.3 / 3.6 /4.2 / 6.1 / 8.1 / 8.3 / 9.3
A30: Aplicação de algoritmos de IA/ML | B30: 5.1 | C30: 4.4 | D30: 2
A31: Implementação de alertas automáticos e detecção de anomalias | B31: 5.2 | C31: 5.1 | D31: 1
A32: Simulação de campanhas e cenários de uso | B32: 5.3 | C32: 5.2 | D32: 1
A33: Testes funcionais e de usabilidade | B33: 6.1 | C33: 5.3 | D33: 1
A34: Testes de responsividade e compatibilidade | B34: 6.2 | C34: 6.1 | D34: 1
A35: Testes de segurança e privacidade (LGPD) | B35: 6.3 | C35: 6.2 | D35: 1
A36: Preparar a infraestrutura para o lançamento nas lojas de aplicativos | B36: 7.1 | C36: 6.3 | D36: 1
A37: Criar materiais de marketing, como vídeos promocionais e descrições claras | B37: 7.2 | C37: 6.3 | D37: 1
A38: Submeter o aplicativo para revisão nas lojas de aplicativos | B38: 7.3 | C38: 6.3 | D38: 1
A39: Entrega da primeira versão aos professores | B39: 8.1 | C39: 6.3 | D39: 1
A40: Ajustes baseados em feedbacks | B40: 8.2 | C40: 8.1 | D40: 1
A41: Entrega oficial da versão final | B41: 8.3 | C41: 8.2 | D41: 1
... A44: Documentação final do projeto | B44: 9.3 | C44: 9.2 | D44: 1

Sheet Diagrama de rede-precedência
A1: Projeto para construir uma casa | G1: PDI -Primeiro dia de início | J1: UDI - Último dia de início | AC1: Diagrama de seta
G2: PDT - Primeito dia de término | J2: UDT - Último dia de término | AD2: Atividade fantasma
B3: Quantos Dias dura o projeto? | G3: FL-Folgas Livres
G4: FT-Folgas totais | M4: 0 | N4: É o caminho crítico
A6: Descrição | B6: Atividade | C6: Dependência | D6: Duração
A7: Definição dos objetivos dos dashboards | B7: 1.1 | D7: 2 | F7: Legenda do NÓ
A8: Formação da equipe e definição dos papéis | B8: 1.2 | D8: 1 | F8: modelo
A9: Levantamento inicial de requisitos e funcionalidades | B9: 1.3 | C9: 1.1 e 1.2 | D9: 3 | F9: atividade | G9: duração
A10: Análise de necessidades da Cannoli e clientes | B10: 2.1 | C10: 1.3 | D10: 4 | F10: PDI | G10: PDT
A11: Definição de requisitos funcionais e não funcionais | B11: 2.2 | C11: 2.1 | D11: 3 | F11: UDI | G11: UDT
A12: Elaboração do cronograma e metas | B12: 2.3 | C12: 2.2 | D12: 1 | F12: FL | G12: FT
A13: Identificação de riscos e plano de mitigação | B13: 2.4 | C13: 2.3 | D13: 4
A14: Navegação e funcionalidades | B14: 3.2 | C14: 2.4 | D14: 5
A15: Protótipos interativos | B15: 3.3 | C15: 2.4 | D15: 3
A16: Interface limpa e intuitiva | B16: 3.5 | C16: 3.2 e 3.3 | D16: 2
A17: Teste de UI / UX | B17: 3.6 | C17: 3.2, 3.3, 3.5 | D17: 1
A18: Modelagem de dados e definição da arquitetura | B18: 4.1 | C18: 3.6 | D18: 7
A19: Implementação do frontend (gráficos, filtros, KPIs) | B19: 4.2 | C19: 4.1 | D19: 3
A20: Implementação do backend (API, lógica do negócio, segurança) | B20: 4.3 | C20: 4.2 | D20: 14
A21: Integração com base de dados | B21: 4.4 | C21: 4.3 | D21: 1 | F21: 1.1 | G21: 2 | X21: 3.2 | Y21: 5
A22: Aplicação de algoritmos de IA/ML | B22: 5.1 | C22: 4.4 | D22: 2 | F22: 0 | G22: =G21+F22 -> 2 | X22: =V25 -> 17 | Y22: =X22+Y21 -> 22
A23: Implementação de alertas automáticos e detecção de anomalias | B23: 5.2 | C23: 5.1 | D23: 1 | F23: =G23-G21 -> 0 | G23: =I26 -> 2 | X23: =Y23-Y21 -> 17 | Y23: =MIN(AD25,AA25) -> 22
A24: Simulação de campanhas e cenários de uso | B24: 5.3 | C24: 5.2 | D24: 1 | F24: =F23-F22 -> 0 | G24: =G23-G22 -> 0 | I24: 1.3 | J24: 3 | L24: 2.1 | M24: 4 | O24: 2.2 | P24: 3 | R24: 2.3 | S24: 1 | U24: 2.4 | V24: 4 | X24: =X23-X22 -> 0 | Y24: =Y23-Y22 -> 0 | AA24: 3.5 | AB24: 2 | AD24: 3.6 | AE24: 1 | AG24: 4.1 | AH24: 7 | AJ24: 4.2 | AK24: 3 | AM24: 4.3 | AN24: 14 | AP24: 4.4 | AQ24: 1 | AS24: 5.1 | AT24: 2 | AV24: 5.2 | AW24: 1 | AY24: 5.3 | AZ24: 1 | BB24: 5.3 | BC24: 1 | BE24: 6.1 | BF24: 1 | BH24: 6.2 | BI24: 1 | BK24: 6.3 | BL24: 1 | BN24: 7.1 | BO24: 1 | BQ24: 7.2 | BR24: 1 | BT24: 7.3 | BU24: 1 | BW24: 8.1 | BX24: 1 | BZ24: 8.2 | CA24: 1 | CC24: 8.3 | CD24: 1 | CF24: 9.1 | CG24: 1 | CI24: 9.2 | CJ24: 1 | CL24: 9.3 | CM24: 1
A25: Testes funcionais e de usabilidade | B25: 6.1 | C25: 5.3 | D25: 1 | I25: =MAX(G22,G28) -> 2 | J25: =I25+J24 -> 5 | L25: =J25 -> 5 | M25: =L25+M24 -> 9 | O25: =M25 -> 9 | P25: =O25+P24 -> 12 | R25: =P25 -> 12 | S25: =R25+S24 -> 13 | U25: =S25 -> 13 | V25: =U25+V24 -> 17 | AA25: =MAX(Y22,Y28) -> 22 | AB25: =AA25+AB24 -> 24 | AD25: =MAX(Y22,Y28,AB25) -> 24 | AE25: =AD25+AE24 -> 25 | AG25: =AE25 -> 25 | AH25: =AG25+AH24 -> 32 | AJ25: =AH25 -> 32 | AK25: =AJ25+AK24 -> 35 | AM25: =AK25 -> 35 | AN25: =AM25+AN24 -> 49 | AP25: =AN25 -> 49 | AQ25: =AP25+AQ24 -> 50 | AS25: =AQ25 -> 50 | AT25: =AS25+AT24 -> 52 | AV25: =AT25 -> 52 | AW25: =AV25+AW24 -> 53 | AY25: =AW25 -> 53 | AZ25: =AY25+AZ24 -> 54 | BB25: =AZ25 -> 54 | BC25: =BB25+BC24 -> 55 | BE25: =BC25 -> 55 | BF25: =BE25+BF24 -> 56 | BH25: =BF25 -> 56 | BI25: =BH25+BI24 -> 57 | BK25: =BI25 -> 57 | BL25: =BK25+BL24 -> 58 | BN25: =BL25 -> 58 | BO25: =BN25+BO24 -> 59 | BQ25: =BO25 -> 59 | BR25: =BQ25+BR24 -> 60 | BT25: =BR25 -> 60 | BU25: =BT25+BU24 -> 61 | BW25: =BU25 -> 61 | BX25: =BW25+BX24 -> 62 | BZ25: =BX25 -> 62 | CA25: =BZ25+CA24 -> 63 | CC25: =CA25 -> 63 | CD25: =CC25+CD24 -> 64 | CF25: =CD25 -> 64 | CG25: =CF25+CG24 -> 65 | CI25: =CG25 -> 65 | CJ25: =CI25+CJ24 -> 66 | CL25: =CJ25 -> 66 | CM25: =CL25+CM24 -> 67
A26: Testes de responsividade e compatibilidade | B26: 6.2 | C26: 6.1 | D26: 1 | I26: =J26-J24 -> 2 | J26: =L26 -> 5 | L26: =M26-M24 -> 5 | M26: =O26 -> 9 | O26: =P26-P24 -> 9 | P26: =R26 -> 12 | R26: =S26-S24 -> 12 | S26: =U26 -> 13 | U26: =V26-V24 -> 13 | V26: =MIN(X23,X29) -> 17 | AA26: =AB26-AB24 -> 22 | AB26: =AB25 -> 24 | AD26: =AE26-AE24 -> 24 | AE26: =AE25 -> 25 | AG26: =AH26-AH24 -> 25 | AH26: =AH25 -> 32 | AJ26: =AK26-AK24 -> 32 | AK26: =AK25 -> 35 | AM26: =AN26-AN24 -> 35 | AN26: =AN25 -> 49 | AP26: =AQ26-AQ24 -> 49 | AQ26: =AQ25 -> 50 | AS26: =AT26-AT24 -> 50 | AT26: =AT25 -> 52 | AV26: =AW26-AW24 -> 52 | AW26: =AW25 -> 53 | AY26: =AZ26-AZ24 -> 53 | AZ26: =AZ25 -> 54 | BB26: =BC26-BC24 -> 54 | BC26: =BC25 -> 55 | BE26: =BF26-BF24 -> 55 | BF26: =BF25 -> 56 | BH26: =BI26-BI24 -> 56 | BI26: =BI25 -> 57 | BK26: =BL26-BL24 -> 57 | BL26: =BL25 -> 58 | BN26: =BO26-BO24 -> 58 | BO26: =BO25 -> 59 | BQ26: =BR26-BR24 -> 59 | BR26: =BR25 -> 60 | BT26: =BU26-BU24 -> 60 | BU26: =BU25 -> 61 | BW26: =BX26-BX24 -> 61 | BX26: =BX25 -> 62 | BZ26: =CA26-CA24 -> 62 | CA26: =CA25 -> 63 | CC26: =CD26-CD24 -> 63 | CD26: =CD25 -> 64 | CF26: =CG26-CG24 -> 64 | CG26: =CG25 -> 65 | CI26: =CJ26-CJ24 -> 65 | CJ26: =CJ25 -> 66 | CL26: =CM26-CM24 -> 66 | CM26: =CM25 -> 67
A27: Testes de segurança e privacidade (LGPD) | B27: 6.3 | C27: 6.2 | D27: 1 | F27: 1.2 | G27: =D8 -> 1 | I27: =I26-I25 -> 0 | J27: =J26-J25 -> 0 | L27: =L26-L25 -> 0 | M27: =M26-M25 -> 0 | O27: =O26-O25 -> 0 | P27: =P26-P25 -> 0 | R27: =R26-R25 -> 0 | S27: =S26-S25 -> 0 | U27: =U26-U25 -> 0 | V27: =V26-V25 -> 0 | X27: 3.3 | Y27: 3 | AA27: =AA26-AA25 -> 0 | AB27: =AB26-AB25 -> 0 | AD27: =AD26-AD25 -> 0 | AE27: =AE26-AE25 -> 0 | AG27: =AG26-AG25 -> 0 | AH27: =AH26-AH25 -> 0 | AJ27: =AJ26-AJ25 -> 0 | AK27: =AK26-AK25 -> 0 | AM27: =AM26-AM25 -> 0 | AN27: =AN26-AN25 -> 0 | AP27: =AP26-AP25 -> 0 | AQ27: =AQ26-AQ25 -> 0 | AS27: =AS26-AS25 -> 0 | AT27: =AT26-AT25 -> 0 | AV27: =AV26-AV25 -> 0 | AW27: =AW26-AW25 -> 0 | AY27: =AY26-AY25 -> 0 | AZ27: =AZ26-AZ25 -> 0 | BB27: =BB26-BB25 -> 0 | BC27: =BC26-BC25 -> 0 | BE27: =BE26-BE25 -> 0 | BF27: =BF26-BF25 -> 0 | BH27: =BH26-BH25 -> 0 | BI27: =BI26-BI25 -> 0 | BK27: =BK26-BK25 -> 0 | BL27: =BL26-BL25 -> 0 | BN27: =BN26-BN25 -> 0 | BO27: =BO26-BO25 -> 0 | BQ27: =BQ26-BQ25 -> 0 | BR27: =BR26-BR25 -> 0 | BT27: =BT26-BT25 -> 0 | BU27: =BU26-BU25 -> 0 | BW27: =BW26-BW25 -> 0 | BX27: =BX26-BX25 -> 0 | BZ27: =BZ26-BZ25 -> 0 | CA27: =CA26-CA25 -> 0 | CC27: =CC26-CC25 -> 0 | CD27: =CD26-CD25 -> 0 | CF27: =CF26-CF25 -> 0 | CG27: =CG26-CG25 -> 0 | CI27: =CI26-CI25 -> 0 | CJ27: =CJ26-CJ25 -> 0 | CL27: =CL26-CL25 -> 0 | CM27: =CM26-CM25 -> 0
A28: Preparar a infraestrutura para o lançamento nas lojas de aplicativos (App Store, Google Play) | B28: 7.1 | C28: 6.3 | D28: 1 | F28: 0 | G28: =F28+G27 -> 1 | X28: =V25 -> 17 | Y28: =X28+Y27 -> 20
A29: Criar materiais de marketing, como vídeos promocionais e descrições claras | B29: 7.2 | C29: 6.3 | D29: 1 | F29: =G29-G27 -> 1 | G29: =I26 -> 2 | X29: =Y29-Y27 -> 19 | Y29: =MIN(AA26,AD26) -> 22
A30: Submeter o aplicativo para revisão nas lojas de aplicativos | B30: 7.3 | C30: 6.3 | D30: 1 | F30: =F29-F28 -> 1 | G30: =G29-G28 -> 1 | X30: =X29-X28 -> 2 | Y30: =Y29-Y28 -> 2
A31: Entrega da primeira versão aos professores | B31: 8.1 | C31: 6.3 | D31: 1
A32: Ajustes baseados em feedbacks | B32: 8.2 | C32: 8.1 | D32: 1
A33: Entrega oficial da versão final | B33: 8.3 | C33: 8.2 | D33: 1
A34: Apresentação do projeto (banner + pitch) | B34: 9.1 | C34: 8.3 | D34: 1
A35: Suporte a dúvidas e melhorias pós-avaliação | B35: 9.2 | C35: 9.1 | D35: 1
A36: Documentação final do projeto | B36: 9.3 | C36: 9.2 | D36: 1

Sheet Gestão de Custo
B2: Previsões de Orçamento | J2: CANNOLI DATAVISION]
C4: 1 | D4: Instruções | F4: Instruções, Histórico de Alterações e as Aprovações
C5: =C4+1 -> 2 | D5: Orçado | F5: Detalhamento dos investimentos orçados
C6: =C5+1 -> 3 | D6: Realizado | F6: Detalhamento dos investimentos realizados
C7: =C6+1 -> 4 | D7: Status | F7: Status comparando Orçado x Realizado
C8: =C7+1 -> 5 | D8: Paramêtros | F8: Parâmetros usados nas outras abas da planilha.
D10: Fonte | E10: https://escritoriodeprojetos.com.br/download/previsoes-do-orcamento/
B14: Controle de Versões
B15: Versão | C15: Data | D15: Autor | E15: Notas da Revisão
B16: 1 | C16: 45216
B17: 2 | C17: 45217
B20: Instruções
B21: Ref. | C21: Aba | D21: Respons | E21: Passos
B22: 0 | C22: Param | D22: PMO | E22: Entre com o Custo do Capital
B23: 1 | C23: Orçado | D23: Gerente de Projetos | E23: Preencher as informações de identificação do projeto (Nome, Solicitante e Patrocionador)
B24: =B23+1 -> 2 | C24: Orçado | D24: Gerente de Projetos | E24: Preencher na coluna B o nome de cada Gasto (B7, B10, ...). No máximo 5, caso tiver mais de 5 agrupar os benefícios ou ajustar planilha. Veja na Aba Param - Coluna C - Tipos de gastos comuns em projetos
B25: =B24+1 -> 3 | C25: Orçado | D25: Gerente de Projetos | E25: Sempre que possível, esclareça como foi calculado o valor dos gastos (C7, C10, ...)
B26: =B25+1 -> 4 | C26: Orçado | D26: Gerente de Projetos | E26: Entrar com o valor dos gastos por ano (D9..M21), se preferir, entre com o valor do crescimento por ano (D8..M20) para todos os gastos
B27: =B26+1 -> 5 | C27: Orçado | D27: Gerente de Projetos | E27: Preenche na coluna B o nome dos custos (B29, B30)
B28: =B27+1 -> 6 | C28: Orçado | D28: Gerente de Projetos | E28: Sempre que possível, esclareça como foi calculado o valor dos custos (C29, C30)
B29: =B28+1 -> 7 | C29: Orçado | D29: Gerente de Projetos | E29: Entrar com o valor dos custos por ano (D27..M31)
B30: =B29+1 -> 8 | C30: Realizado | D30: Gerente de Projetos | E30: Entre com o valor realizado mês a mês. Caso não necessitar registrar os detalhes, pode incluir o valor total na linha 39 [Investimento total]
B31: =B30+1 -> 9
B32: =B31+1 -> 10
B33: =B32+1 -> 11
B34: =B33+1 -> 12
B36: Aprovações
B37: Ref. | C37: Data | D37: Participante | E37: Assinatura
B38: 1
B39: 2
B40: 3

Sheet Orçado
A2: Identificação do Projeto | C2: Mês
A3: Nome do Projeto | B3: Cannoli DataVision | D3: 45894 | E3: 45925 | F3: 45955 | G3: 45986 | H3: TOTAL
A4: Patrocinador | B4: Faculdade FECAP | C4: 0 | D4: 1 | E4: 2 | F4: 3 | G4: 4
A5: Investimento inicial Total | C5: 0 | D5: R$6000,00 | E5: R$ 14.000,00 | F5: R$10.000,00 | G5: R$ 8.000,00 | H5: R$38.000,00
A6: Investimento Acumulado | B6: 0 | C6: 0 | D6: R$6.000,00 | E6: R$ 20.000,00 | F6: R$ 30.000,00 | G6: R$ 38.000,00
A7: Orçado | B7: Explicação
A8: Investimento c/ taxa de crescimento | B8: Para facilitar o cálculo do gasto baseado em uma taxa de crescimento.
A9: Iniciação | B9: Gasto referente ao start do projeto, desde o estudo, mapeamento de funcionalidade e formação de time | C9: 0 | D9: 300 | E9: 0 | F9: 0 | G9: 0 | H9: 300
B10: Taxa de crescimento de investimento de 0% ao mês MOM | E10: 0 | F10: 0 | G10: 0
A11: Planejamento | B11: Tudo que tange o mapeamento inicial do planejamento, como plano de exercicio e requisitos, mapas de academias e parques e afins. | C11: 0 | D11: 500 | E11: 500 | F11: 500 | G11: 500 | H11: 2000
B12: Taxa de crescimento de investimento de 33% ao mês MOM | E12: 1 | F12: 0 | G12: 0
A13: Design e Prototipagem | B13: Todo processo que compete ao desenvolvimento da funcionalidade em sua camada de Wire, Layout, experiência, ou seja, UX. | C13: 0 | D13: 50 | E13: 100 | F13: 100 | G13: 50 | H13: 300
B14: Taxa de crescimento de investimento de 660% ao mês MOM | E14: 2 | F14: 0 | G14: 0
A15: Desenvolvimento | B15: Desenvolvimento do frontend, backend e todo processo de desenvolvimento. | C15: 0 | D15: 500 | E15: 1500 | F15: 1000 | G15: 1000 | H15: 4000
B16: Taxa de crescimento de investimento de 0% ao mês MOM | E16: 0 | F16: 0 | G16: 0
A17: INTEGRAÇÃO DE INTELIGÊNCIA ARTIFICIAL E SIMULAÇÕES | B17: Foco na segurança e integração da plataforma. | C17: 0 | D17: 1200 | E17: 500 | F17: 600 | G17: 600 | H17: 3100
B18: Taxa de crescimento de investimento de 66% ao mês MOM | E18: 0 | F18: 0 | G18: 2
A19: Teste | B19: Verificar as funcionalidades, realizar testes e possíveis correções | C19: 0 | D19: 0 | E19: 500 | F19: 250 | G19: 750 | H19: 1500
B20: Taxa de crescimento de investimento de 18% ao mês MOM | E20: 0.44 | F20: 0 | G20: 0.1
A21: Lançamento (Stakeholders internos) | B21: Tudo que tange aos stakeholders | C21: 0 | D21: 3300 | E21: 6800 | F21: 2500 | G21: 3500 | H21: 16000
B22: Taxa de crescimento de investimento de 0% ao mês MOM | E22: 0 | F22: 0 | G22: 0
A23: Pós-lançamento (Stakeholders internos) | B23: Tudo que tange o pós lançamento. | C23: 0 | D23: 0 | E23: 0 | F23: 0 | G23: 0 | H23: 0
B24: Taxa de crescimento de investimento de 10% ao mês MOM | E24: 0 | F24: 0 | G24: 0.6
A25: PÓS-LANÇAMENTO E APRESENTAÇÃO FINAL | B25: Todo processo de marketing e divulgação. | C25: 0 | D25: 0 | E25: 0 | F25: 1000 | G25: 1600 | H25: 3000
B26: Taxa de crescimento de investimento de 10% ao mês MOM | E26: 0.1 | F26: 0 | G26: 0
A27: Expansão | B27: Feedback e adapção | C27: 0 | D27: 0 | E27: 4000 | F27: 2050 | G27: 2300 | H27: 8350
A32: Indicadores Financeiros
A34: NPV/VPL | C34: 42400
A35: Payback | C35: 0
A36: ROI | C36: -0.14

Sheet Realizado
B2: =#REF! -> #REF! | E2: Mês
B3: Nome do Projeto | C3: Cannoli DataVision | E3: 45870 | F3: 45901 | G3: 45931 | H3: 45962 | I3: TOTAL
B4: Patrocinador | C4: Faculdade FECAP | D4: 0 | E4: 1 | F4: =E4+1 -> 2 | G4: =F4+1 -> 3 | H4: =G4+1 -> 4
B5: Investimento Total | E5: 6350 | F5: 15300 | G5: 11350 | H5: 9400 | I5: 42400
B6: Investimento Acumulado | E6: =D6+E5 -> 6350 | F6: =E6+F5 -> 21650 | G6: =F6+G5 -> 33000 | H6: =G6+H5 -> 42400
B7: Realizado | C7: Explicação
B8: Investimento c/ taxa de crescimento
B9: Iniciação | C9: Gasto referente a Definição dos objetivos dos dashboards, Formação da equipe e definição dos papéis e Levantamento inicial de requisitos e funcionalidades. | D9: 0 | E9: 300 | F9: 0 | G9: 0 | H9: 0 | I9: 300
F10: 0 | G10: 0 | H10: 0
B11: Planejamento | C11: Tudo que tange o mapeamento inicial do planejamento, como plano de exercicio e requisitos, mapas de academias e parques e afins. | D11: 0 | E11: 500 | F11: 500 | G11: 500 | H11: 500 | I11: =SUM(E11:H11) -> 2000
F12: 0 | G12: =F12 -> 0 | H12: =G12 -> 0
B13: Design e Prototipagem | C13: Todo processo que compete ao desenvolvimento da funcionalidade em sua camada de Wire, Layout, experiência, ou seja, UX. | D13: 0 | E13: 50 | F13: 100 | G13: 100 | H13: 50 | I13: =SUM(E13:H13) -> 300
F14: 2 | G14: 0 | H14: =G14 -> 0
B15: Desenvolvimento | C15: Desenvolvimento do frontend, backend e todo processo de desenvolvimento. | D15: 0 | E15: 500 | F15: 1500 | G15: 1000 | H15: 1000 | I15: =SUM(E15:H15) -> 4000
F16: 0 | G16: 0 | H16: =G16 -> 0
B17: INTEGRAÇÃO DE INTELIGÊNCIA ARTIFICIAL E SIMULAÇÕES | C17: Foco na segurança e integração da plataforma. | D17: 0 | E17: 1200 | F17: 1200 | G17: 600 | H17: 600 | I17: 3600
F18: 0 | G18: 0 | H18: =200% -> 2
B19: Testes | C19: Verificar as funcionalidades, realizar testes e possíveis correções | D19: 0 | E19: 0 | F19: 500 | G19: 250 | H19: 750 | I19: =SUM(E19:H19) -> 1500
F20: 0.52 | G20: 0 | H20: =G20 -> 0
B21: Lançamento (Stakeholders internos) | C21: Tudo que tange aos stakeholders | D21: 0 | E21: 2950 | F21: 7500 | G21: 3300 | H21: 4500 | I21: =SUM(E21:H21) -> 18250
F22: 0 | G22: =F22 -> 0 | H22: =G22 -> 0
B23: Pós-lançamento (Stakeholders internos) | C23: Tudo que tange o pós lançamento. | D23: 0 | E23: 0 | F23: =E23*(1+F22) -> 0 | G23: =F23*(1+G22) -> 0 | H23: =G23*(1+H22) -> 0 | I23: =SUM(E23:H23) -> 0
F24: 0 | G24: =F24 -> 0 | H24: 1
B25: PÓS-LANÇAMENTO E APRESENTAÇÃO FINAL | C25: Todo processo de apresentação final. | D25: 0 | E25: 0 | F25: 0 | G25: 1000 | H25: =2000 -> 2000 | I25: =SUM(E25:H25) -> 3000
F26: 0 | G26: =F26 -> 0 | H26: =G26 -> 0
B27: Expansão | C27: Feedback e adapção | D27: 0 | E27: 0 | F27: 4000 | G27: 2600 | H27: 2300 | I27: =SUM(E27:H27) -> 8900

Sheet Gráfico -Status
B2: Períodos | C2: No Período (R$) | E2: Acumulado (R$) | G2: Desvio (R$) | H2: Desvio %
B3: Mês | C3: Orçado | D3: Realizado | E3: Orçado | F3: Realizado | G3: Diferença dos realizados
B4: 0 | C4: 0 | D4: 0 | E4: 0 | F4: 0 | G4: 0 | H4: 0
B5: 1 | C5: 6000 | D5: 6350 | E5: 6000 | F5: 6350 | G5: 350 | H5: 0.06
B6: 2 | C6: 14000 | D6: 15300 | E6: 20000 | F6: 21650 | G6: 1650 | H6: 0.08
B7: 3 | C7: 10000 | D7: 11350 | E7: 30000 | F7: 33300 | G7: 3000 | H7: 0.1
B8: 4 | C8: 8000 | D8: 9400 | E8: 38000 | F8: 42400 | G8: 2400 | H8: 0.12
B9: Total | C9: 38000 | D9: 42400
B10: Saldo Final | C10: -4400

Sheet Param
B2: Variável | C2: Tipo de Benefício | D2: Custo do Capital
B3: Explicação | D3: Retorno Requerido do Investimento
B4: Domínio ou Valor | C4: Aumento de Receita | D4: 0.06
C5: Aumento de Produtividade
C6: Aumento da Capacidade Produtiva
C7: Redução do Turn-over
C8: Redução de retrabalho
C9: Redução dos custos da não qualidade
C10: Redução das reclamações dos clientes
C11: Redução dos custos
B15: Parametros a serem configurados inicialmente
B16: Projeto
B17: Nome do projeto | C17: Cannoli DataVision
B18: Mês de início | C18: 45891
B19: Patrocinador | C19: FECAP

Sheet Capa
B5: Informações sobre o projeto
B6: Projeto | E6: Cannoli DataVision
B7: Gerente Responsável | E7: Matheus Antero
B8: Data da avaliação | E8: dd/mm/aaaa
B9: Histórico da avaliação de riscos
B10: dd/mm/aaaa | C10: Comentário

Sheet Identificar
A1: Identificação dos Riscos | AF1: Probabilidade | AI1: Impacto
A4: =Capa!E6 -> Cannoli DataVision
AF5: Muito Baixa - 1 | AG5: 1 | AI5: Muito Baixo - 1 | AJ5: 1
A6: ID | B6: Fase ou | D6: Declaração do Risco | G6: Resp. | H6: Estratégia de Resposta | I6: Plano de Prevenção | J6: Plano de Contingência | L6: Severidade (X,Y) | AF6: Baixa - 2 | AG6: 2 | AI6: Muito Baixo - 2 | AJ6: 2
B7: Recurso | C7: Classificação | D7: CAUSA (Começa a frase com "Como Resultado ...") | E7: RISCO (Começar a frase com "Pode ocorrer ...") | F7: CONSEQUÊNCIA (Começar a frase com "O que acarretaria ...") | K7: Riscos Colaterais | AF7: Moderada - 3 | AG7: 3 | AI7: Baixo - 3 | AJ7: 3
A8: R01 | B8: Recursos (Pessoas) | C8: Técnico | D8: Como resultado da equipe ser composta por alunos | E8: Pode ocorrer dificuldade técnica ou indisponibilidade de tempo | F8: O que acarretaria atraso nas Sprints e bugs no produto final | G8: EQUIPE | H8: Mitigar | I8: Realizar workshops técnicos curtos sobre IA e LGPD antes das fases. | J8: Ter um mentor técnico de sobreaviso para ajudar a equipe. | K8: Queda na moral da equipe; Dependência excessiva do mentor. | L8: =Qualificar!K8 -> 0.04 | AF8: Alta - 4 | AG8: 4 | AI8: Baixo - 4 | AJ8: 4
A9: R02 | B9: Escopo | C9: Negócio | D9: Como resultado de solicitações de novas funcionalidades pelos stakeholders | E9: Pode ocorrer aumento do escopo do projeto (scope creep) | F9: O que acarretaria atraso no cronograma e estouro do orçamento | G9: EQUIPE | H9: Evitar | I9: Definir um processo formal de "Congelamento de Escopo" | J9: Negociar com o P.O. a troca de funcionalidades (nova por antiga). | K9: Insatisfação do stakeholder que teve a funcionalidade trocada. | L9: =Qualificar!K9 -> 0.08
A10: R03 | B10: Custo | C10: Financeiro | D10: Como resultado de um planejamento de custos subestimado | E10: Pode ocorrer que o custo real continue maior que o orçado | F10: O que acarretaria falta de verba para as fases finais | G10: EQUIPE | H10: Aceitar (Ativo) | I10: Criar uma reserva de contingência de 10% sobre o custo restante. | J10: Apresentar o desvio ao patrocinador (FECAP) com plano de ação. | K10: Aumento da burocracia e monitoramento pelo patrocinador (FECAP). | L10: =Qualificar!K10 -> 0.16
A11: R04 | B11: Técnico (IA/ML) | C11: Técnico | D11: Como resultado da alta complexidade dos algoritmos de IA/ML | E11: Pode ocorrer que as funcionalidades de alertas e simulação não funcionem | F11: O que acarretaria o comprometimento da principal entrega de valor (IA) | G11: EQUIPE | H11: Mitigar | I11: Realizar uma Prova de Conceito (PoC) dos algoritmos antes da fase 5. | J11: Usar uma biblioteca de IA mais simples ou reduzir o escopo da simulação. | K11: Perda de valor percebido do produto final (ser visto como "menos inovador"). | L11: =Qualificar!K11 -> 0.08
A12: R05 | B12: Técnico (LGPD) | C12: Legal | D12: Como resultado da implementação incorreta dos testes de privacidade (LGPD) | E12: Pode ocorrer que o aplicativo não esteja em conformidade com a LGPD | F12: O que acarretaria risco legal para a Cannoli/FECAP e rejeição dos usuários | G12: EQUIPE | H12: Mitigar | I12: Criar um checklist de verificação de LGPD | J12: Contratar uma consultoria jurídica rápida para validar os pontos de coleta. | K12: Novos atrasos técnicos devido a mudanças de arquitetura exigidas pela consultoria. | L12: =Qualificar!K12 -> 0.01
A13: R06 | B13: Externo (Lojas App) | C13: Técnico | D13: Como resultado do aplicativo não atender às diretrizes da Apple ou Google | E13: Pode ocorrer a rejeição do aplicativo nas lojas (App Store / Google Play) | F13: O que acarretaria um atraso significativo no Lançamento e na entrega final | G13: EQUIPE | H13: Transferir / Mitigar | I13: Ler as diretrizes de submissão | J13: Submeter o dash o mais cedo possível, prevendo tempo para re-submissão. | K13: Risco de perder a data da Apresentação Final | L13: =Qualificar!K13 -> 0.02
A14: R07 | B14: Stakeholders | C14: Negócio | D14: Como resultado da versão entregue aos professores não atender às expectativas | E14: Pode ocorrer um volume muito alto de pedidos de ajustes | F14: O que acarretaria atraso na entrega oficial da versão final | G14: EQUIPE | H14: Mitigar | I14: Realizar uma "pré-validação" com um grupo menor de professores. | J14: Alocar 3 dias no cronograma (buffer) para ajustes pós-feedback. | K14: Introdução de novos bugs (regressão) ao fazer ajustes apressados. | L14: =Qualificar!K14 -> 0.04
A15: R08 | B15: Cronograma | C15: Gerenciamento | D15: Como resultado de atrasos acumulados nas fases de Desenvolvimento e Integração | E15: Pode ocorrer a compressão do cronograma das fases seguintes (Testes, Lançamento) | F15: O que acarretaria redução da qualidade dos testes e falha na data da Apresentação | G15: EQUIPE | H15: Mitigar | I15: Monitorar semanalmente o "caminho crítico" do projeto. | J15: Reduzir o escopo de funcionalidades não-essenciais da fase "Expansão". | K15: Redução do caso de negócio (business case) do projeto. | L15: =Qualificar!K15 -> 0.02
A16: R09
A17: R10
A18: R11
A19: R12
A20: R13
A21: R14
A22: R15
A23: R16
A24: R17
A25: R18
A26: R19 | L26: =Qualificar!K26
A27: R20 | L27: =Qualificar!K27

Sheet Qualificar
A1: Qualificação dos Riscos | AF1: Probabilidade | AI1: Impacto
K2: Base Custo | M2: 10000 | N2: R$
K3: Base Prazo | M3: 30 | N3: dias úteis
A4: =Identificar!A4 -> Cannoli DataVision
AF5: Muito Baixa - 1 | AG5: 1 | AI5: Muito Baixo - 1 | AJ5: 1
A6: ID | B6: Declaração do Risco | E6: Resp. | F6: Probabilidade do risco virar incidente (Y) | G6: Avaliação de Impacto (X) | K6: Severidade (Y,X) | M6: Custo | N6: Prazo | AF6: Baixa - 2 | AG6: 2 | AI6: Muito Baixo - 2 | AJ6: 2
B7: CAUSA (Começa a frase com "Como Resultado ...") | C7: RISCO (Começar a frase com "Pode ocorrer ...") | D7: CONSEQÜÊNCIA (Começar a frase com "O que acarretaria ...") | G7: Aumento no Custo (X1) | H7: Desvio no Cronograma (X2) | I7: (X1*X2) | J7: Resultado do Impacto (X1+X2) | L7: Riscos Colaterais | AF7: Moderada - 3 | AG7: 3 | AI7: Baixo - 3 | AJ7: 3
A8: =IF(Identificar!A8<>"",Identificar!A8,"") -> R01 | B8: =IF(Identificar!D8<>"",Identificar!D8,"") -> Como resultado da equipe ser composta por alunos | C8: =IF(Identificar!E8<>"",Identificar!E8,"") -> Pode ocorrer dificuldade técnica ou indisponibilidade de tempo | D8: =IF(Identificar!F8<>"",Identificar!F8,"") -> O que acarretaria atraso nas Sprints e bugs no produto final | E8: =IF(Identificar!G8<>"",Identificar!G8,"") -> EQUIPE | F8: Alta - 0,4 | G8: Entre 5% e 10% - 1,10 | H8: Entre 5% e 10% - 2,10 | I8: =IF(G8<>"",IF(H8<>"",RIGHT(G8,4)*RIGHT(H8,4),""),"") -> 2.31 | J8: =IF(I8<>"",VLOOKUP(I8,'Sensibilidade ao Risco'!$E$2:$F$30,2,FALSE),"") -> Baixa - 0,10 | K8: =IF(F8<>"",IF(J8<>"",(RIGHT(J8,3))*(RIGHT(F8,3)),""),"") -> 0.04 | L8: Atraso no projeto e aumento nos custos | M8: =ROUNDUP(Quantificar!G8/Qualificar!$M$2,2) -> 0.2 | N8: =ROUNDUP(Quantificar!H8/Qualificar!$M$3,2) -> 0.17 | AF8: Alta - 4 | AG8: 4 | AI8: Baixo - 4 | AJ8: 4
A9: =IF(Identificar!A9<>"",Identificar!A9,"") -> R02 | B9: =IF(Identificar!D9<>"",Identificar!D9,"") -> Como resultado de solicitações de novas funcionalidades pelos stakeholders | C9: =IF(Identificar!E9<>"",Identificar!E9,"") -> Pode ocorrer aumento do escopo do projeto (scope creep) | D9: =IF(Identificar!F9<>"",Identificar!F9,"") -> O que acarretaria atraso no cronograma e estouro do orçamento | E9: =IF(Identificar!G9<>"",Identificar!G9,"") -> EQUIPE | F9: Moderada - 0,2 | G9: Entre 10% e 20% - 1,20 | H9: Entre 10% e 20% - 2,20 | I9: =IF(G9<>"",IF(H9<>"",RIGHT(G9,4)*RIGHT(H9,4),""),"") -> 2.64 | J9: =IF(I9<>"",VLOOKUP(I9,'Sensibilidade ao Risco'!$E$2:$F$30,2,FALSE),"") -> Alta - 0,40 | K9: =IF(F9<>"",IF(J9<>"",(RIGHT(J9,3))*(RIGHT(F9,3)),""),"") -> 0.08 | M9: =ROUNDUP(Quantificar!G9/Qualificar!$M$2,2) -> 0.5 | N9: =ROUNDUP(Quantificar!H9/Qualificar!$M$3,2) -> 0.34
A10: =IF(Identificar!A10<>"",Identificar!A10,"") -> R03 | B10: =IF(Identificar!D10<>"",Identificar!D10,"") -> Como resultado de um planejamento de custos subestimado | C10: =IF(Identificar!E10<>"",Identificar!E10,"") -> Pode ocorrer que o custo real continue maior que o orçado | D10: =IF(Identificar!F10<>"",Identificar!F10,"") -> O que acarretaria falta de verba para as fases finais | E10: =IF(Identificar!G10<>"",Identificar!G10,"") -> EQUIPE | F10: Muito Alta - 0,8 | G10: Entre 20% e 40% - 1,40 | H10: Menor que 5% - 2,05 | I10: =IF(G10<>"",IF(H10<>"",RIGHT(G10,4)*RIGHT(H10,4),""),"") -> 2.87 | J10: =IF(I10<>"",VLOOKUP(I10,'Sensibilidade ao Risco'!$E$2:$F$30,2,FALSE),"") -> Moderada - 0,20 | K10: =IF(F10<>"",IF(J10<>"",(RIGHT(J10,3))*(RIGHT(F10,3)),""),"") -> 0.16 | M10: =ROUNDUP(Quantificar!G10/Qualificar!$M$2,2) -> 0.8 | N10: =ROUNDUP(Quantificar!H10/Qualificar!$M$3,2) -> 0.1
A11: =IF(Identificar!A11<>"",Identificar!A11,"") -> R04 | B11: =IF(Identificar!D11<>"",Identificar!D11,"") -> Como resultado da alta complexidade dos algoritmos de IA/ML | C11: =IF(Identificar!E11<>"",Identificar!E11,"") -> Pode ocorrer que as funcionalidades de alertas e simulação não funcionem | D11: =IF(Identificar!F11<>"",Identificar!F11,"") -> O que acarretaria o comprometimento da principal entrega de valor (IA) | E11: =IF(Identificar!G11<>"",Identificar!G11,"") -> EQUIPE | F11: Moderada - 0,2 | G11: Entre 10% e 20% - 1,20 | H11: Entre 10% e 20% - 2,20 | I11: =IF(G11<>"",IF(H11<>"",RIGHT(G11,4)*RIGHT(H11,4),""),"") -> 2.64 | J11: =IF(I11<>"",VLOOKUP(I11,'Sensibilidade ao Risco'!$E$2:$F$30,2,FALSE),"") -> Alta - 0,40 | K11: =IF(F11<>"",IF(J11<>"",(RIGHT(J11,3))*(RIGHT(F11,3)),""),"") -> 0.08 | M11: =ROUNDUP(Quantificar!G11/Qualificar!$M$2,2) -> 0.4 | N11: =ROUNDUP(Quantificar!H11/Qualificar!$M$3,2) -> 0.34
A12: =IF(Identificar!A12<>"",Identificar!A12,"") -> R05 | B12: =IF(Identificar!D12<>"",Identificar!D12,"") -> Como resultado da implementação incorreta dos testes de privacidade (LGPD) | C12: =IF(Identificar!E12<>"",Identificar!E12,"") -> Pode ocorrer que o aplicativo não esteja em conformidade com a LGPD | D12: =IF(Identificar!F12<>"",Identificar!F12,"") -> O que acarretaria risco legal para a Cannoli/FECAP e rejeição dos usuários | E12: =IF(Identificar!G12<>"",Identificar!G12,"") -> EQUIPE | F12: Baixa - 0,1 | G12: Entre 5% e 10% - 1,10 | H12: Entre 5% e 10% - 2,10 | I12: =IF(G12<>"",IF(H12<>"",RIGHT(G12,4)*RIGHT(H12,4),""),"") -> 2.31 | J12: =IF(I12<>"",VLOOKUP(I12,'Sensibilidade ao Risco'!$E$2:$F$30,2,FALSE),"") -> Baixa - 0,10 | K12: =IF(F12<>"",IF(J12<>"",(RIGHT(J12,3))*(RIGHT(F12,3)),""),"") -> 0.01 | M12: =ROUNDUP(Quantificar!G12/Qualificar!$M$2,2) -> 0.3 | N12: =ROUNDUP(Quantificar!H12/Qualificar!$M$3,2) -> 0.17
A13: =IF(Identificar!A13<>"",Identificar!A13,"") -> R06 | B13: =IF(Identificar!D13<>"",Identificar!D13,"") -> Como resultado do aplicativo não atender às diretrizes da Apple ou Google | C13: =IF(Identificar!E13<>"",Identificar!E13,"") -> Pode ocorrer a rejeição do aplicativo nas lojas (App Store / Google Play) | D13: =IF(Identificar!F13<>"",Identificar!F13,"") -> O que acarretaria um atraso significativo no Lançamento e na entrega final | E13: =IF(Identificar!G13<>"",Identificar!G13,"") -> EQUIPE | F13: Moderada - 0,2 | G13: Menor que 5% - 1,05 | H13: Entre 5% e 10% - 2,10 | I13: =IF(G13<>"",IF(H13<>"",RIGHT(G13,4)*RIGHT(H13,4),""),"") -> 2.205 | J13: =IF(I13<>"",VLOOKUP(I13,'Sensibilidade ao Risco'!$E$2:$F$30,2,FALSE),"") -> Baixa - 0,10 | K13: =IF(F13<>"",IF(J13<>"",(RIGHT(J13,3))*(RIGHT(F13,3)),""),"") -> 0.02 | M13: =ROUNDUP(Quantificar!G13/Qualificar!$M$2,2) -> 0.15 | N13: =ROUNDUP(Quantificar!H13/Qualificar!$M$3,2) -> 0.24
A14: =IF(Identificar!A14<>"",Identificar!A14,"") -> R07 | B14: =IF(Identificar!D14<>"",Identificar!D14,"") -> Como resultado da versão entregue aos professores não atender às expectativas | C14: =IF(Identificar!E14<>"",Identificar!E14,"") -> Pode ocorrer um volume muito alto de pedidos de ajustes | D14: =IF(Identificar!F14<>"",Identificar!F14,"") -> O que acarretaria atraso na entrega oficial da versão final | E14: =IF(Identificar!G14<>"",Identificar!G14,"") -> EQUIPE | F14: Alta - 0,4 | G14: Entre 5% e 10% - 1,10 | H14: Entre 5% e 10% - 2,10 | I14: =IF(G14<>"",IF(H14<>"",RIGHT(G14,4)*RIGHT(H14,4),""),"") -> 2.31 | J14: =IF(I14<>"",VLOOKUP(I14,'Sensibilidade ao Risco'!$E$2:$F$30,2,FALSE),"") -> Baixa - 0,10 | K14: =IF(F14<>"",IF(J14<>"",(RIGHT(J14,3))*(RIGHT(F14,3)),""),"") -> 0.04 | M14: =ROUNDUP(Quantificar!G14/Qualificar!$M$2,2) -> 0.2 | N14: =ROUNDUP(Quantificar!H14/Qualificar!$M$3,2) -> 0.17
A15: =IF(Identificar!A15<>"",Identificar!A15,"") -> R08 | B15: =IF(Identificar!D15<>"",Identificar!D15,"") -> Como resultado de atrasos acumulados nas fases de Desenvolvimento e Integração | C15: =IF(Identificar!E15<>"",Identificar!E15,"") -> Pode ocorrer a compressão do cronograma das fases seguintes (Testes, Lançamento) | D15: =IF(Identificar!F15<>"",Identificar!F15,"") -> O que acarretaria redução da qualidade dos testes e falha na data da Apresentação | E15: =IF(Identificar!G15<>"",Identificar!G15,"") -> EQUIPE | F15: Moderada - 0,2 | G15: Entre 5% e 10% - 1,10 | H15: Entre 5% e 10% - 2,10 | I15: =IF(G15<>"",IF(H15<>"",RIGHT(G15,4)*RIGHT(H15,4),""),"") -> 2.31 | J15: =IF(I15<>"",VLOOKUP(I15,'Sensibilidade ao Risco'!$E$2:$F$30,2,FALSE),"") -> Baixa - 0,10 | K15: =IF(F15<>"",IF(J15<>"",(RIGHT(J15,3))*(RIGHT(F15,3)),""),"") -> 0.02 | M15: =ROUNDUP(Quantificar!G15/Qualificar!$M$2,2) -> 0.3 | N15: =ROUNDUP(Quantificar!H15/Qualificar!$M$3,2) -> 0.24
A16: =IF(Identificar!A16<>"",Identificar!A16,"") -> R09 | B16: =IF(Identificar!D16<>"",Identificar!D16,"") | C16: =IF(Identificar!E16<>"",Identificar!E16,"") | D16: =IF(Identificar!F16<>"",Identificar!F16,"") | E16: =IF(Identificar!G16<>"",Identificar!G16,"") | I16: =IF(G16<>"",IF(H16<>"",RIGHT(G16,4)*RIGHT(H16,4),""),"") | J16: =IF(I16<>"",VLOOKUP(I16,'Sensibilidade ao Risco'!$E$2:$F$30,2,FALSE),"") | K16: =IF(F16<>"",IF(J16<>"",(RIGHT(J16,3))*(RIGHT(F16,3)),""),"") | M16: =ROUNDUP(Quantificar!G16/Qualificar!$M$2,2) -> 0 | N16: =ROUNDUP(Quantificar!H16/Qualificar!$M$3,2) -> 0
A17: =IF(Identificar!A17<>"",Identificar!A17,"") -> R10 | B17: =IF(Identificar!D17<>"",Identificar!D17,"") | C17: =IF(Identificar!E17<>"",Identificar!E17,"") | D17: =IF(Identificar!F17<>"",Identificar!F17,"") | E17: =IF(Identificar!G17<>"",Identificar!G17,"") | I17: =IF(G17<>"",IF(H17<>"",RIGHT(G17,4)*RIGHT(H17,4),""),"") | J17: =IF(I17<>"",VLOOKUP(I17,'Sensibilidade ao Risco'!$E$2:$F$30,2,FALSE),"") | K17: =IF(F17<>"",IF(J17<>"",(RIGHT(J17,3))*(RIGHT(F17,3)),""),"") | M17: =ROUNDUP(Quantificar!G17/Qualificar!$M$2,2) -> 0 | N17: =ROUNDUP(Quantificar!H17/Qualificar!$M$3,2) -> 0
A18: =IF(Identificar!A18<>"",Identificar!A18,"") -> R11 | B18: =IF(Identificar!D18<>"",Identificar!D18,"") | C18: =IF(Identificar!E18<>"",Identificar!E18,"") | D18: =IF(Identificar!F18<>"",Identificar!F18,"") | E18: =IF(Identificar!G18<>"",Identificar!G18,"") | I18: =IF(G18<>"",IF(H18<>"",RIGHT(G18,4)*RIGHT(H18,4),""),"") | J18: =IF(I18<>"",VLOOKUP(I18,'Sensibilidade ao Risco'!$E$2:$F$30,2,FALSE),"") | K18: =IF(F18<>"",IF(J18<>"",(RIGHT(J18,3))*(RIGHT(F18,3)),""),"") | M18: =ROUNDUP(Quantificar!G18/Qualificar!$M$2,2) -> 0 | N18: =ROUNDUP(Quantificar!H18/Qualificar!$M$3,2) -> 0
A19: =IF(Identificar!A19<>"",Identificar!A19,"") -> R12 | B19: =IF(Identificar!D19<>"",Identificar!D19,"") | C19: =IF(Identificar!E19<>"",Identificar!E19,"") | D19: =IF(Identificar!F19<>"",Identificar!F19,"") | E19: =IF(Identificar!G19<>"",Identificar!G19,"") | I19: =IF(G19<>"",IF(H19<>"",RIGHT(G19,4)*RIGHT(H19,4),""),"") | J19: =IF(I19<>"",VLOOKUP(I19,'Sensibilidade ao Risco'!$E$2:$F$30,2,FALSE),"") | K19: =IF(F19<>"",IF(J19<>"",(RIGHT(J19,3))*(RIGHT(F19,3)),""),"") | M19: =ROUNDUP(Quantificar!G19/Qualificar!$M$2,2) -> 0 | N19: =ROUNDUP(Quantificar!H19/Qualificar!$M$3,2) -> 0
A20: =IF(Identificar!A20<>"",Identificar!A20,"") -> R13 | B20: =IF(Identificar!D20<>"",Identificar!D20,"") | C20: =IF(Identificar!E20<>"",Identificar!E20,"") | D20: =IF(Identificar!F20<>"",Identificar!F20,"") | E20: =IF(Identificar!G20<>"",Identificar!G20,"") | I20: =IF(G20<>"",IF(H20<>"",RIGHT(G20,4)*RIGHT(H20,4),""),"") | J20: =IF(I20<>"",VLOOKUP(I20,'Sensibilidade ao Risco'!$E$2:$F$30,2,FALSE),"") | K20: =IF(F20<>"",IF(J20<>"",(RIGHT(J20,3))*(RIGHT(F20,3)),""),"") | M20: =ROUNDUP(Quantificar!G20/Qualificar!$M$2,2) -> 0 | N20: =ROUNDUP(Quantificar!H20/Qualificar!$M$3,2) -> 0
A21: =IF(Identificar!A21<>"",Identificar!A21,"") -> R14 | B21: =IF(Identificar!D21<>"",Identificar!D21,"") | C21: =IF(Identificar!E21<>"",Identificar!E21,"") | D21: =IF(Identificar!F21<>"",Identificar!F21,"") | E21: =IF(Identificar!G21<>"",Identificar!G21,"") | I21: =IF(G21<>"",IF(H21<>"",RIGHT(G21,4)*RIGHT(H21,4),""),"") | J21: =IF(I21<>"",VLOOKUP(I21,'Sensibilidade ao Risco'!$E$2:$F$30,2,FALSE),"") | K21: =IF(F21<>"",IF(J21<>"",(RIGHT(J21,3))*(RIGHT(F21,3)),""),"") | M21: =ROUNDUP(Quantificar!G21/Qualificar!$M$2,2) -> 0 | N21: =ROUNDUP(Quantificar!H21/Qualificar!$M$3,2) -> 0
A22: =IF(Identificar!A22<>"",Identificar!A22,"") -> R15 | B22: =IF(Identificar!D22<>"",Identificar!D22,"") | C22: =IF(Identificar!E22<>"",Identificar!E22,"") | D22: =IF(Identificar!F22<>"",Identificar!F22,"") | E22: =IF(Identificar!G22<>"",Identificar!G22,"") | I22: =IF(G22<>"",IF(H22<>"",RIGHT(G22,4)*RIGHT(H22,4),""),"") | J22: =IF(I22<>"",VLOOKUP(I22,'Sensibilidade ao Risco'!$E$2:$F$30,2,FALSE),"") | K22: =IF(F22<>"",IF(J22<>"",(RIGHT(J22,3))*(RIGHT(F22,3)),""),"") | M22: =ROUNDUP(Quantificar!G22/Qualificar!$M$2,2) -> 0 | N22: =ROUNDUP(Quantificar!H22/Qualificar!$M$3,2) -> 0
A23: =IF(Identificar!A23<>"",Identificar!A23,"") -> R16 | B23: =IF(Identificar!D23<>"",Identificar!D23,"") | C23: =IF(Identificar!E23<>"",Identificar!E23,"") | D23: =IF(Identificar!F23<>"",Identificar!F23,"") | E23: =IF(Identificar!G23<>"",Identificar!G23,"") | I23: =IF(G23<>"",IF(H23<>"",RIGHT(G23,4)*RIGHT(H23,4),""),"") | J23: =IF(I23<>"",VLOOKUP(I23,'Sensibilidade ao Risco'!$E$2:$F$30,2,FALSE),"") | K23: =IF(F23<>"",IF(J23<>"",(RIGHT(J23,3))*(RIGHT(F23,3)),""),"") | M23: =ROUNDUP(Quantificar!G23/Qualificar!$M$2,2) -> 0 | N23: =ROUNDUP(Quantificar!H23/Qualificar!$M$3,2) -> 0
A24: =IF(Identificar!A24<>"",Identificar!A24,"") -> R17 | B24: =IF(Identificar!D24<>"",Identificar!D24,"") | C24: =IF(Identificar!E24<>"",Identificar!E24,"") | D24: =IF(Identificar!F24<>"",Identificar!F24,"") | E24: =IF(Identificar!G24<>"",Identificar!G24,"") | I24: =IF(G24<>"",IF(H24<>"",RIGHT(G24,4)*RIGHT(H24,4),""),"") | J24: =IF(I24<>"",VLOOKUP(I24,'Sensibilidade ao Risco'!$E$2:$F$30,2,FALSE),"") | K24: =IF(F24<>"",IF(J24<>"",(RIGHT(J24,3))*(RIGHT(F24,3)),""),"") | M24: =ROUNDUP(Quantificar!G24/Qualificar!$M$2,2) -> 0 | N24: =ROUNDUP(Quantificar!H24/Qualificar!$M$3,2) -> 0
A25: =IF(Identificar!A25<>"",Identificar!A25,"") -> R18 | B25: =IF(Identificar!D25<>"",Identificar!D25,"") | C25: =IF(Identificar!E25<>"",Identificar!E25,"") | D25: =IF(Identificar!F25<>"",Identificar!F25,"") | E25: =IF(Identificar!G25<>"",Identificar!G25,"") | I25: =IF(G25<>"",IF(H25<>"",RIGHT(G25,4)*RIGHT(H25,4),""),"") | J25: =IF(I25<>"",VLOOKUP(I25,'Sensibilidade ao Risco'!$E$2:$F$30,2,FALSE),"") | K25: =IF(F25<>"",IF(J25<>"",(RIGHT(J25,3))*(RIGHT(F25,3)),""),"") | M25: =ROUNDUP(Quantificar!G25/Qualificar!$M$2,2) -> 0 | N25: =ROUNDUP(Quantificar!H25/Qualificar!$M$3,2) -> 0
A26: =IF(Identificar!A26<>"",Identificar!A26,"") -> R19 | B26: =IF(Identificar!D26<>"",Identificar!D26,"") | C26: =IF(Identificar!E26<>"",Identificar!E26,"") | D26: =IF(Identificar!F26<>"",Identificar!F26,"") | E26: =IF(Identificar!G26<>"",Identificar!G26,"") | I26: =IF(G26<>"",IF(H26<>"",RIGHT(G26,4)*RIGHT(H26,4),""),"") | J26: =IF(I26<>"",VLOOKUP(I26,'Sensibilidade ao Risco'!$E$2:$F$30,2,FALSE),"") | K26: =IF(F26<>"",IF(J26<>"",(RIGHT(J26,3))*(RIGHT(F26,3)),""),"") | M26: =ROUNDUP(Quantificar!G26/Qualificar!$M$2,2) -> 0 | N26: =ROUNDUP(Quantificar!H26/Qualificar!$M$3,2) -> 0
A27: =IF(Identificar!A27<>"",Identificar!A27,"") -> R20 | B27: =IF(Identificar!D27<>"",Identificar!D27,"") | C27: =IF(Identificar!E27<>"",Identificar!E27,"") | D27: =IF(Identificar!F27<>"",Identificar!F27,"") | E27: =IF(Identificar!G27<>"",Identificar!G27,"") | I27: =IF(G27<>"",IF(H27<>"",RIGHT(G27,4)*RIGHT(H27,4),""),"") | J27: =IF(I27<>"",VLOOKUP(I27,'Sensibilidade ao Risco'!$E$2:$F$30,2,FALSE),"") | K27: =IF(F27<>"",IF(J27<>"",(RIGHT(J27,3))*(RIGHT(F27,3)),""),"") | M27: =ROUNDUP(Quantificar!G27/Qualificar!$M$2,2) -> 0 | N27: =ROUNDUP(Quantificar!H27/Qualificar!$M$3,2) -> 0
F48: Insignificante - 1,05 | G48: Insignificante - 2,05 | H48: Muito baixa - 0,05
F49: Menor que 5% - 1,10 | G49: Menor que 5% - 2,10 | H49: Baixa - 0,1
F50: Entre 5% e 10% - 1,20 | G50: Entre 5% e 10% - 2,20 | H50: Moderada - 0,2
F51: Entre 10% e 20% - 1,40 | G51: Entre 10% e 20% - 2,40 | H51: Alta - 0,4
F52: Maior que 20% - 1,80 | G52: Maior que 20% - 2,80 | H52: Muito Alta - 0,8

Sheet Quantificar
A1: Quantificação dos Riscos | AB1: Probabilidade | AE1: Impacto
A4: =Identificar!A4 -> Cannoli DataVision
